{
 "cells": [
  {
   "cell_type": "markdown",
   "id": "69f98f39",
   "metadata": {},
   "source": [
    "# Age and Gender Recognition\n",
    "\n",
    "### github.com/rafaroman18\n",
    "\n",
    "This project consist of classifying in real time the gender of a person and their age. We will be using a dataset of faces and a library of python to activate the camera of our laptop."
   ]
  },
  {
   "cell_type": "code",
   "execution_count": 8,
   "id": "bb0d86c7",
   "metadata": {},
   "outputs": [],
   "source": [
    "# Imports\n",
    "import cv2 as cv\n",
    "import os\n",
    "os.environ[\"TF_CPP_MIN_LOG_LEVEL\"] = \"2\"\n",
    "\n",
    "import tensorflow as tf\n",
    "import pandas as pd\n",
    "from tensorflow import keras\n",
    "from tensorflow.keras import layers\n",
    "import keras.applications\n",
    "\n",
    "import pathlib"
   ]
  },
  {
   "cell_type": "markdown",
   "id": "be115555",
   "metadata": {},
   "source": [
    "First of all we will create a model to predict the gender and age of the people in the camera. We will train this model with a face dataset and we will use a pretrained model: XCEPTION. \n",
    "\n",
    "We will use the UTKFace Dataset, so we have to create a function to transform the images locally into a tensorflow dataset."
   ]
  },
  {
   "cell_type": "markdown",
   "id": "448ad6e0",
   "metadata": {},
   "source": [
    "## MAYBE IT WOULD BE INTERESTING TO CREATE CLASSES OF AGE SO WE CAN CLASSIFY 10 CLASSES: \n",
    "* 0-10\n",
    "* 20-30\n",
    "* 30-40\n",
    "* 40-50\n",
    "* 50-60\n",
    "* 60-70\n",
    "* 70-80\n",
    "* 80-90\n",
    "* 90-100\n",
    "* 100+"
   ]
  },
  {
   "cell_type": "markdown",
   "id": "e057ec2c",
   "metadata": {},
   "source": [
    "## KEEP IN MIND: DATA ANALYSIS\n",
    "\n",
    "## DATA AUGMENTATION"
   ]
  },
  {
   "cell_type": "code",
   "execution_count": 3,
   "id": "5c84c998",
   "metadata": {},
   "outputs": [],
   "source": [
    "batch_size = 32\n",
    "img_height = 200\n",
    "img_width = 200\n",
    "\n",
    "path = 'face_dataset/'\n",
    "ds_train = tf.data.Dataset.list_files(str(pathlib.Path(path+'*.jpg')))\n",
    "\n",
    "def process_path(file_path):\n",
    "    image = tf.io.read_file(file_path)\n",
    "    image = tf.image.decode_jpeg(image, channels=1)\n",
    "    label = tf.strings.split(file_path, '\\\\')[1]\n",
    "    label = tf.strings.split(label, '_')[0]# First test: only Age \":2]\"\n",
    "    label = tf.strings.to_number(label, out_type=tf.int64)\n",
    "    \n",
    "    return image, label\n",
    "\n",
    "ds_train = ds_train.map(process_path).batch(batch_size)"
   ]
  },
  {
   "cell_type": "code",
   "execution_count": null,
   "id": "eb59f1f5",
   "metadata": {},
   "outputs": [],
   "source": [
    "# https://towardsdatascience.com/building-a-multi-output-convolutional-neural-network-with-keras-ed24c7bc1178"
   ]
  },
  {
   "cell_type": "code",
   "execution_count": null,
   "id": "35e58fd0",
   "metadata": {},
   "outputs": [],
   "source": []
  },
  {
   "cell_type": "code",
   "execution_count": null,
   "id": "9ce6873a",
   "metadata": {},
   "outputs": [],
   "source": []
  },
  {
   "cell_type": "code",
   "execution_count": 19,
   "id": "57ea0ea6",
   "metadata": {},
   "outputs": [
    {
     "name": "stdout",
     "output_type": "stream",
     "text": [
      "Model: \"model_3\"\n",
      "_________________________________________________________________\n",
      " Layer (type)                Output Shape              Param #   \n",
      "=================================================================\n",
      " input_12 (InputLayer)       [(None, 200, 200, 3)]     0         \n",
      "                                                                 \n",
      " xception (Functional)       (None, 7, 7, 2048)        20861480  \n",
      "                                                                 \n",
      " global_average_pooling2d_4   (None, 2048)             0         \n",
      " (GlobalAveragePooling2D)                                        \n",
      "                                                                 \n",
      " dropout_4 (Dropout)         (None, 2048)              0         \n",
      "                                                                 \n",
      " dense_4 (Dense)             (None, 1)                 2049      \n",
      "                                                                 \n",
      " age (Activation)            (None, 1)                 0         \n",
      "                                                                 \n",
      "=================================================================\n",
      "Total params: 20,863,529\n",
      "Trainable params: 2,049\n",
      "Non-trainable params: 20,861,480\n",
      "_________________________________________________________________\n"
     ]
    }
   ],
   "source": [
    "xception = keras.applications.Xception(\n",
    "    weights=\"imagenet\",\n",
    "    input_shape=(img_height, img_width, 3),\n",
    "    include_top=False,\n",
    ")\n",
    "\n",
    "xception.trainable = False\n",
    "\n",
    "inputs = keras.Input(shape=(img_height, img_width, 3))\n",
    "\n",
    "x = xception(inputs, training=False)\n",
    "\n",
    "x = keras.layers.GlobalAveragePooling2D()(x)\n",
    "\n",
    "x = keras.layers.Dropout(0.2)(x)\n",
    "\n",
    "x = keras.layers.Dense(1)(x)\n",
    "\n",
    "outputs = keras.layers.Activation('relu', name='age')(x)\n",
    "\n",
    "model = keras.Model(inputs, outputs)\n",
    "model.summary()"
   ]
  },
  {
   "cell_type": "code",
   "execution_count": 23,
   "id": "74e33b19",
   "metadata": {},
   "outputs": [
    {
     "name": "stdout",
     "output_type": "stream",
     "text": [
      "Epoch 1/5\n",
      "WARNING:tensorflow:Model was constructed with shape (None, 200, 200, 3) for input KerasTensor(type_spec=TensorSpec(shape=(None, 200, 200, 3), dtype=tf.float32, name='input_12'), name='input_12', description=\"created by layer 'input_12'\"), but it was called on an input with incompatible shape (None, None, None, 1).\n",
      "WARNING:tensorflow:Model was constructed with shape (None, 200, 200, 3) for input KerasTensor(type_spec=TensorSpec(shape=(None, 200, 200, 3), dtype=tf.float32, name='input_11'), name='input_11', description=\"created by layer 'input_11'\"), but it was called on an input with incompatible shape (None, None, None, 1).\n"
     ]
    },
    {
     "ename": "ValueError",
     "evalue": "in user code:\n\n    File \"C:\\Users\\Rafa\\anaconda3\\lib\\site-packages\\keras\\engine\\training.py\", line 1051, in train_function  *\n        return step_function(self, iterator)\n    File \"C:\\Users\\Rafa\\anaconda3\\lib\\site-packages\\keras\\engine\\training.py\", line 1040, in step_function  **\n        outputs = model.distribute_strategy.run(run_step, args=(data,))\n    File \"C:\\Users\\Rafa\\anaconda3\\lib\\site-packages\\keras\\engine\\training.py\", line 1030, in run_step  **\n        outputs = model.train_step(data)\n    File \"C:\\Users\\Rafa\\anaconda3\\lib\\site-packages\\keras\\engine\\training.py\", line 889, in train_step\n        y_pred = self(x, training=True)\n    File \"C:\\Users\\Rafa\\anaconda3\\lib\\site-packages\\keras\\utils\\traceback_utils.py\", line 67, in error_handler\n        raise e.with_traceback(filtered_tb) from None\n    File \"C:\\Users\\Rafa\\anaconda3\\lib\\site-packages\\keras\\engine\\input_spec.py\", line 248, in assert_input_compatibility\n        raise ValueError(\n\n    ValueError: Exception encountered when calling layer \"xception\" (type Functional).\n    \n    Input 0 of layer \"block1_conv1\" is incompatible with the layer: expected axis -1 of input shape to have value 3, but received input with shape (None, None, None, 1)\n    \n    Call arguments received by layer \"xception\" (type Functional):\n      • inputs=tf.Tensor(shape=(None, None, None, 1), dtype=float32)\n      • training=False\n      • mask=None\n",
     "output_type": "error",
     "traceback": [
      "\u001b[1;31m---------------------------------------------------------------------------\u001b[0m",
      "\u001b[1;31mValueError\u001b[0m                                Traceback (most recent call last)",
      "Cell \u001b[1;32mIn [23], line 7\u001b[0m\n\u001b[0;32m      1\u001b[0m model\u001b[38;5;241m.\u001b[39mcompile(\n\u001b[0;32m      2\u001b[0m     optimizer \u001b[38;5;241m=\u001b[39m keras\u001b[38;5;241m.\u001b[39moptimizers\u001b[38;5;241m.\u001b[39mAdam(),\n\u001b[0;32m      3\u001b[0m     loss \u001b[38;5;241m=\u001b[39m keras\u001b[38;5;241m.\u001b[39mlosses\u001b[38;5;241m.\u001b[39mMeanSquaredError(),\n\u001b[0;32m      4\u001b[0m     metrics \u001b[38;5;241m=\u001b[39m [keras\u001b[38;5;241m.\u001b[39mmetrics\u001b[38;5;241m.\u001b[39mAccuracy()]\n\u001b[0;32m      5\u001b[0m     )\n\u001b[1;32m----> 7\u001b[0m history \u001b[38;5;241m=\u001b[39m \u001b[43mmodel\u001b[49m\u001b[38;5;241;43m.\u001b[39;49m\u001b[43mfit\u001b[49m\u001b[43m(\u001b[49m\u001b[43mds_train\u001b[49m\u001b[43m,\u001b[49m\u001b[43m \u001b[49m\u001b[43mepochs\u001b[49m\u001b[38;5;241;43m=\u001b[39;49m\u001b[38;5;241;43m5\u001b[39;49m\u001b[43m,\u001b[49m\u001b[43m \u001b[49m\u001b[43mvalidation_data\u001b[49m\u001b[38;5;241;43m=\u001b[39;49m\u001b[43mds_train\u001b[49m\u001b[43m)\u001b[49m\n",
      "File \u001b[1;32m~\\anaconda3\\lib\\site-packages\\keras\\utils\\traceback_utils.py:67\u001b[0m, in \u001b[0;36mfilter_traceback.<locals>.error_handler\u001b[1;34m(*args, **kwargs)\u001b[0m\n\u001b[0;32m     65\u001b[0m \u001b[38;5;28;01mexcept\u001b[39;00m \u001b[38;5;167;01mException\u001b[39;00m \u001b[38;5;28;01mas\u001b[39;00m e:  \u001b[38;5;66;03m# pylint: disable=broad-except\u001b[39;00m\n\u001b[0;32m     66\u001b[0m   filtered_tb \u001b[38;5;241m=\u001b[39m _process_traceback_frames(e\u001b[38;5;241m.\u001b[39m__traceback__)\n\u001b[1;32m---> 67\u001b[0m   \u001b[38;5;28;01mraise\u001b[39;00m e\u001b[38;5;241m.\u001b[39mwith_traceback(filtered_tb) \u001b[38;5;28;01mfrom\u001b[39;00m \u001b[38;5;28mNone\u001b[39m\n\u001b[0;32m     68\u001b[0m \u001b[38;5;28;01mfinally\u001b[39;00m:\n\u001b[0;32m     69\u001b[0m   \u001b[38;5;28;01mdel\u001b[39;00m filtered_tb\n",
      "File \u001b[1;32m~\\AppData\\Local\\Temp\\__autograph_generated_fileudnqxe9q.py:15\u001b[0m, in \u001b[0;36mouter_factory.<locals>.inner_factory.<locals>.tf__train_function\u001b[1;34m(iterator)\u001b[0m\n\u001b[0;32m     13\u001b[0m \u001b[38;5;28;01mtry\u001b[39;00m:\n\u001b[0;32m     14\u001b[0m     do_return \u001b[38;5;241m=\u001b[39m \u001b[38;5;28;01mTrue\u001b[39;00m\n\u001b[1;32m---> 15\u001b[0m     retval_ \u001b[38;5;241m=\u001b[39m ag__\u001b[38;5;241m.\u001b[39mconverted_call(ag__\u001b[38;5;241m.\u001b[39mld(step_function), (ag__\u001b[38;5;241m.\u001b[39mld(\u001b[38;5;28mself\u001b[39m), ag__\u001b[38;5;241m.\u001b[39mld(iterator)), \u001b[38;5;28;01mNone\u001b[39;00m, fscope)\n\u001b[0;32m     16\u001b[0m \u001b[38;5;28;01mexcept\u001b[39;00m:\n\u001b[0;32m     17\u001b[0m     do_return \u001b[38;5;241m=\u001b[39m \u001b[38;5;28;01mFalse\u001b[39;00m\n",
      "\u001b[1;31mValueError\u001b[0m: in user code:\n\n    File \"C:\\Users\\Rafa\\anaconda3\\lib\\site-packages\\keras\\engine\\training.py\", line 1051, in train_function  *\n        return step_function(self, iterator)\n    File \"C:\\Users\\Rafa\\anaconda3\\lib\\site-packages\\keras\\engine\\training.py\", line 1040, in step_function  **\n        outputs = model.distribute_strategy.run(run_step, args=(data,))\n    File \"C:\\Users\\Rafa\\anaconda3\\lib\\site-packages\\keras\\engine\\training.py\", line 1030, in run_step  **\n        outputs = model.train_step(data)\n    File \"C:\\Users\\Rafa\\anaconda3\\lib\\site-packages\\keras\\engine\\training.py\", line 889, in train_step\n        y_pred = self(x, training=True)\n    File \"C:\\Users\\Rafa\\anaconda3\\lib\\site-packages\\keras\\utils\\traceback_utils.py\", line 67, in error_handler\n        raise e.with_traceback(filtered_tb) from None\n    File \"C:\\Users\\Rafa\\anaconda3\\lib\\site-packages\\keras\\engine\\input_spec.py\", line 248, in assert_input_compatibility\n        raise ValueError(\n\n    ValueError: Exception encountered when calling layer \"xception\" (type Functional).\n    \n    Input 0 of layer \"block1_conv1\" is incompatible with the layer: expected axis -1 of input shape to have value 3, but received input with shape (None, None, None, 1)\n    \n    Call arguments received by layer \"xception\" (type Functional):\n      • inputs=tf.Tensor(shape=(None, None, None, 1), dtype=float32)\n      • training=False\n      • mask=None\n"
     ]
    }
   ],
   "source": [
    "model.compile(\n",
    "    optimizer = keras.optimizers.Adam(),\n",
    "    loss = keras.losses.MeanSquaredError(),\n",
    "    metrics = [keras.metrics.Accuracy()]\n",
    "    )\n",
    "\n",
    "history = model.fit(ds_train, epochs=5, validation_data=ds_train)"
   ]
  },
  {
   "cell_type": "code",
   "execution_count": null,
   "id": "3539ea1b",
   "metadata": {},
   "outputs": [],
   "source": []
  },
  {
   "cell_type": "code",
   "execution_count": null,
   "id": "91cd58ac",
   "metadata": {},
   "outputs": [],
   "source": []
  },
  {
   "cell_type": "code",
   "execution_count": null,
   "id": "8dab40bf",
   "metadata": {},
   "outputs": [],
   "source": []
  },
  {
   "cell_type": "code",
   "execution_count": null,
   "id": "908af321",
   "metadata": {},
   "outputs": [],
   "source": []
  },
  {
   "cell_type": "code",
   "execution_count": null,
   "id": "e64d8205",
   "metadata": {},
   "outputs": [],
   "source": []
  },
  {
   "cell_type": "code",
   "execution_count": null,
   "id": "8af1134e",
   "metadata": {},
   "outputs": [],
   "source": []
  },
  {
   "cell_type": "code",
   "execution_count": null,
   "id": "fbcf45a1",
   "metadata": {},
   "outputs": [],
   "source": []
  },
  {
   "cell_type": "code",
   "execution_count": null,
   "id": "8fc30cf1",
   "metadata": {},
   "outputs": [],
   "source": [
    "face_cascade = cv.CascadeClassifier('haarcascade_frontalface_default.xml')\n",
    "cap = cv.VideoCapture(0)\n",
    "\n",
    "\n",
    "if not cap.isOpened():\n",
    "    print(\"Cannot open camera\")\n",
    "    exit()\n",
    "\n",
    "try:\n",
    "    while True:\n",
    "        # Capture frame-by-frame\n",
    "        ret, frame = cap.read()\n",
    "        \n",
    "        # if frame is read correctly ret is True\n",
    "        if not ret:\n",
    "            print(\"Can't receive frame (stream end?). Exiting ...\")\n",
    "            break\n",
    "        \n",
    "        faces = face_cascade.detectMultiScale(\n",
    "            frame,\n",
    "            scaleFactor=1.1,\n",
    "            minNeighbors=5,\n",
    "            flags=cv.CASCADE_SCALE_IMAGE\n",
    "        )\n",
    "        \n",
    "        for (x, y, w, h) in faces:\n",
    "            cv.rectangle(frame, (x, y), (x+w, y+h), (0, 255, 0), 2)\n",
    "\n",
    "        # Display the resulting frame\n",
    "        cv.imshow('frame', frame)\n",
    "        if cv.waitKey(1) == ord('q'):\n",
    "            break\n",
    "finally:\n",
    "    # Finally, release capture\n",
    "    cap.release()\n",
    "    cv.destroyAllWindows()"
   ]
  },
  {
   "cell_type": "code",
   "execution_count": null,
   "id": "553e376d",
   "metadata": {},
   "outputs": [],
   "source": []
  }
 ],
 "metadata": {
  "kernelspec": {
   "display_name": "Python 3 (ipykernel)",
   "language": "python",
   "name": "python3"
  },
  "language_info": {
   "codemirror_mode": {
    "name": "ipython",
    "version": 3
   },
   "file_extension": ".py",
   "mimetype": "text/x-python",
   "name": "python",
   "nbconvert_exporter": "python",
   "pygments_lexer": "ipython3",
   "version": "3.9.13"
  }
 },
 "nbformat": 4,
 "nbformat_minor": 5
}
